I'm sorry, but an uncaught exception occurred.

While running game code:
  File "game/script.rpy", line 496, in script
    Mascto "Reassure_1"
Exception: Sayer 'Mascto' is not defined.

-- Full Traceback ------------------------------------------------------------

Full traceback:
  File "game/script.rpy", line 496, in script
    Mascto "Reassure_1"
  File "C:\Users\jchoi\Downloads\renpy-8.1.3-sdk\renpy\ast.py", line 890, in execute
    who = eval_who(self.who, self.who_fast)
  File "C:\Users\jchoi\Downloads\renpy-8.1.3-sdk\renpy\ast.py", line 783, in eval_who
    raise Exception("Sayer '%s' is not defined." % who)
Exception: Sayer 'Mascto' is not defined.

Windows-10-10.0.19045 AMD64
Ren'Py 8.1.3.23091805
Fate of Love 1.0
Fri Dec  1 13:47:11 2023
